[2023-04-28T21:44:16.167+0000] {taskinstance.py:1084} INFO - Dependencies all met for dep_context=non-requeueable deps ti=<TaskInstance: get_todays_gamesv4.call_games manual__2023-04-28T21:44:11.183038+00:00 [queued]>
[2023-04-28T21:44:16.178+0000] {taskinstance.py:1084} INFO - Dependencies all met for dep_context=requeueable deps ti=<TaskInstance: get_todays_gamesv4.call_games manual__2023-04-28T21:44:11.183038+00:00 [queued]>
[2023-04-28T21:44:16.179+0000] {taskinstance.py:1282} INFO - 
--------------------------------------------------------------------------------
[2023-04-28T21:44:16.179+0000] {taskinstance.py:1283} INFO - Starting attempt 1 of 1
[2023-04-28T21:44:16.180+0000] {taskinstance.py:1284} INFO - 
--------------------------------------------------------------------------------
[2023-04-28T21:44:16.206+0000] {taskinstance.py:1303} INFO - Executing <Task(PythonOperator): call_games> on 2023-04-28 21:44:11.183038+00:00
[2023-04-28T21:44:16.230+0000] {standard_task_runner.py:82} INFO - Running: ['***', 'tasks', 'run', 'get_todays_gamesv4', 'call_games', 'manual__2023-04-28T21:44:11.183038+00:00', '--job-id', '414', '--raw', '--subdir', 'DAGS_FOLDER/todays_games.py', '--cfg-path', '/tmp/tmptlhvvvfb']
[2023-04-28T21:44:16.231+0000] {standard_task_runner.py:83} INFO - Job 414: Subtask call_games
[2023-04-28T21:44:16.231+0000] {standard_task_runner.py:55} INFO - Started process 963 to run task
[2023-04-28T21:44:16.372+0000] {task_command.py:388} INFO - Running <TaskInstance: get_todays_gamesv4.call_games manual__2023-04-28T21:44:11.183038+00:00 [running]> on host f789e77bc70a
[2023-04-28T21:44:16.531+0000] {taskinstance.py:1511} INFO - Exporting the following env vars:
AIRFLOW_CTX_DAG_OWNER=***
AIRFLOW_CTX_DAG_ID=get_todays_gamesv4
AIRFLOW_CTX_TASK_ID=call_games
AIRFLOW_CTX_EXECUTION_DATE=2023-04-28T21:44:11.183038+00:00
AIRFLOW_CTX_TRY_NUMBER=1
AIRFLOW_CTX_DAG_RUN_ID=manual__2023-04-28T21:44:11.183038+00:00
[2023-04-28T21:44:16.789+0000] {taskinstance.py:1775} ERROR - Task failed with exception
Traceback (most recent call last):
  File "/home/airflow/.local/lib/python3.7/site-packages/airflow/operators/python.py", line 175, in execute
    return_value = self.execute_callable()
  File "/home/airflow/.local/lib/python3.7/site-packages/airflow/operators/python.py", line 192, in execute_callable
    return self.python_callable(*self.op_args, **self.op_kwargs)
  File "/opt/airflow/dags/todays_games.py", line 34, in _call_games
    games = schedule(start_date=start_date,end_date=end_date,team=team)
  File "/opt/airflow/dags/statsapi/__init__.py", line 94, in schedule
    r = get("schedule", params)
  File "/opt/airflow/dags/statsapi/__init__.py", line 1736, in get
    r.raise_for_status()
  File "/home/airflow/.local/lib/python3.7/site-packages/requests/models.py", line 1021, in raise_for_status
    raise HTTPError(http_error_msg, response=self)
requests.exceptions.HTTPError: 400 Client Error: Bad Request for url: https://statsapi.mlb.com/api/v1/schedule?startDate=04/28/2023&endDate=04/28/2023&teamId=New%20York%20Yankees&sportId=1&hydrate=decisions,probablePitcher(note),linescore,broadcasts,game(content(media(epg))),seriesStatus
[2023-04-28T21:44:16.803+0000] {taskinstance.py:1326} INFO - Marking task as FAILED. dag_id=get_todays_gamesv4, task_id=call_games, execution_date=20230428T214411, start_date=20230428T214416, end_date=20230428T214416
[2023-04-28T21:44:16.821+0000] {standard_task_runner.py:105} ERROR - Failed to execute job 414 for task call_games (400 Client Error: Bad Request for url: https://statsapi.mlb.com/api/v1/schedule?startDate=04/28/2023&endDate=04/28/2023&teamId=New%20York%20Yankees&sportId=1&hydrate=decisions,probablePitcher(note),linescore,broadcasts,game(content(media(epg))),seriesStatus; 963)
[2023-04-28T21:44:16.858+0000] {local_task_job.py:212} INFO - Task exited with return code 1
[2023-04-28T21:44:16.894+0000] {taskinstance.py:2585} INFO - 0 downstream tasks scheduled from follow-on schedule check
